2025-05-10 17:46:26,406 INFO    MainThread:9122 [wandb_setup.py:_flush():70] Current SDK version is 0.19.11
2025-05-10 17:46:26,406 INFO    MainThread:9122 [wandb_setup.py:_flush():70] Configure stats pid to 9122
2025-05-10 17:46:26,406 INFO    MainThread:9122 [wandb_setup.py:_flush():70] Loading settings from /home/mathis/.config/wandb/settings
2025-05-10 17:46:26,406 INFO    MainThread:9122 [wandb_setup.py:_flush():70] Loading settings from /home/mathis/Bureau/Stage - Code/StageTests/wandb/settings
2025-05-10 17:46:26,406 INFO    MainThread:9122 [wandb_setup.py:_flush():70] Loading settings from environment variables
2025-05-10 17:46:26,407 INFO    MainThread:9122 [wandb_init.py:setup_run_log_directory():724] Logging user logs to wandb/wandb/run-20250510_174626-o6p1zop0/logs/debug.log
2025-05-10 17:46:26,407 INFO    MainThread:9122 [wandb_init.py:setup_run_log_directory():725] Logging internal logs to wandb/wandb/run-20250510_174626-o6p1zop0/logs/debug-internal.log
2025-05-10 17:46:26,407 INFO    MainThread:9122 [wandb_init.py:monkeypatch_ipython():643] configuring jupyter hooks <wandb.sdk.wandb_init._WandbInit object at 0x7a0013fdc770>
2025-05-10 17:46:26,408 INFO    MainThread:9122 [wandb_init.py:init():852] calling init triggers
2025-05-10 17:46:26,408 INFO    MainThread:9122 [wandb_init.py:init():857] wandb.init called with sweep_config: {}
config: {'_wandb': {}}
2025-05-10 17:46:26,408 INFO    MainThread:9122 [wandb_init.py:init():893] starting backend
2025-05-10 17:46:26,408 INFO    MainThread:9122 [wandb_init.py:init():897] sending inform_init request
2025-05-10 17:46:26,413 INFO    MainThread:9122 [backend.py:_multiprocessing_setup():101] multiprocessing start_methods=fork,spawn,forkserver, using: spawn
2025-05-10 17:46:26,414 INFO    MainThread:9122 [wandb_init.py:init():907] backend started and connected
2025-05-10 17:46:26,422 INFO    MainThread:9122 [wandb_run.py:_label_probe_notebook():1376] probe notebook
2025-05-10 17:46:26,546 INFO    MainThread:9122 [wandb_init.py:init():1005] updated telemetry
2025-05-10 17:46:26,547 INFO    MainThread:9122 [wandb_init.py:init():1029] communicating run to backend with 90.0 second timeout
2025-05-10 17:46:27,271 INFO    MainThread:9122 [wandb_init.py:init():1104] starting run threads in backend
2025-05-10 17:46:27,517 INFO    MainThread:9122 [wandb_run.py:_console_start():2573] atexit reg
2025-05-10 17:46:27,517 INFO    MainThread:9122 [wandb_run.py:_redirect():2421] redirect: wrap_raw
2025-05-10 17:46:27,517 INFO    MainThread:9122 [wandb_run.py:_redirect():2490] Wrapping output streams.
2025-05-10 17:46:27,517 INFO    MainThread:9122 [wandb_run.py:_redirect():2513] Redirects installed.
2025-05-10 17:46:27,519 INFO    MainThread:9122 [wandb_init.py:init():1150] run started, returning control to user process
2025-05-10 17:46:27,796 INFO    MainThread:9122 [wandb_run.py:_config_callback():1436] config_cb None None {'predicts': 'x_0', 'guidance': None, 'guidance_scale': 1.0}
2025-05-10 17:52:01,142 WARNING MsgRouterThr:9122 [router.py:message_loop():63] [no run ID] message_loop has been closed
Traceback (most recent call last):
  File "/home/mathis/anaconda3/lib/python3.12/site-packages/wandb/sdk/lib/sock_client.py", line 208, in _read_packet_bytes
    data = self._sock.recv(self._bufsize)
           ^^^^^^^^^^^^^^^^^^^^^^^^^^^^^^
ConnectionResetError: [Errno 104] Connection reset by peer

The above exception was the direct cause of the following exception:

Traceback (most recent call last):
  File "/home/mathis/anaconda3/lib/python3.12/site-packages/wandb/sdk/interface/router_sock.py", line 27, in _read_message
    return self._sock_client.read_server_response(timeout=1)
           ^^^^^^^^^^^^^^^^^^^^^^^^^^^^^^^^^^^^^^^^^^^^^^^^^
  File "/home/mathis/anaconda3/lib/python3.12/site-packages/wandb/sdk/lib/sock_client.py", line 235, in read_server_response
    data = self._read_packet_bytes(timeout=timeout)
           ^^^^^^^^^^^^^^^^^^^^^^^^^^^^^^^^^^^^^^^^
  File "/home/mathis/anaconda3/lib/python3.12/site-packages/wandb/sdk/lib/sock_client.py", line 212, in _read_packet_bytes
    raise SockClientClosedError from e
wandb.sdk.lib.sock_client.SockClientClosedError

The above exception was the direct cause of the following exception:

Traceback (most recent call last):
  File "/home/mathis/anaconda3/lib/python3.12/site-packages/wandb/sdk/interface/router.py", line 56, in message_loop
    msg = self._read_message()
          ^^^^^^^^^^^^^^^^^^^^
  File "/home/mathis/anaconda3/lib/python3.12/site-packages/wandb/sdk/interface/router_sock.py", line 29, in _read_message
    raise MessageRouterClosedError from e
wandb.sdk.interface.router.MessageRouterClosedError
2025-05-10 17:52:01,144 INFO    MsgRouterThr:9122 [mailbox.py:close():129] [no run ID] Closing mailbox, abandoning 1 handles.
2025-05-10 17:52:01,156 ERROR   MainThread:9122 [redirect.py:_on_write():664] [no run ID] error in stderr callback
Traceback (most recent call last):
  File "/home/mathis/anaconda3/lib/python3.12/site-packages/IPython/core/interactiveshell.py", line 3577, in run_code
    exec(code_obj, self.user_global_ns, self.user_ns)
  File "/tmp/ipykernel_9122/2957431058.py", line 12, in <module>
    trainer.fit(flow_model, train_dataloaders=loader)
  File "/home/mathis/anaconda3/lib/python3.12/site-packages/pytorch_lightning/trainer/trainer.py", line 561, in fit
    call._call_and_handle_interrupt(
  File "/home/mathis/anaconda3/lib/python3.12/site-packages/pytorch_lightning/trainer/call.py", line 48, in _call_and_handle_interrupt
    return trainer_fn(*args, **kwargs)
           ^^^^^^^^^^^^^^^^^^^^^^^^^^^
  File "/home/mathis/anaconda3/lib/python3.12/site-packages/pytorch_lightning/trainer/trainer.py", line 599, in _fit_impl
    self._run(model, ckpt_path=ckpt_path)
  File "/home/mathis/anaconda3/lib/python3.12/site-packages/pytorch_lightning/trainer/trainer.py", line 1012, in _run
    results = self._run_stage()
              ^^^^^^^^^^^^^^^^^
  File "/home/mathis/anaconda3/lib/python3.12/site-packages/pytorch_lightning/trainer/trainer.py", line 1056, in _run_stage
    self.fit_loop.run()
  File "/home/mathis/anaconda3/lib/python3.12/site-packages/pytorch_lightning/loops/fit_loop.py", line 216, in run
    self.advance()
  File "/home/mathis/anaconda3/lib/python3.12/site-packages/pytorch_lightning/loops/fit_loop.py", line 455, in advance
    self.epoch_loop.run(self._data_fetcher)
  File "/home/mathis/anaconda3/lib/python3.12/site-packages/pytorch_lightning/loops/training_epoch_loop.py", line 151, in run
    self.on_advance_end(data_fetcher)
  File "/home/mathis/anaconda3/lib/python3.12/site-packages/pytorch_lightning/loops/training_epoch_loop.py", line 386, in on_advance_end
    raise SIGTERMException
pytorch_lightning.utilities.exceptions.SIGTERMException

During handling of the above exception, another exception occurred:

Traceback (most recent call last):
  File "/home/mathis/anaconda3/lib/python3.12/site-packages/wandb/sdk/lib/redirect.py", line 662, in _on_write
    cb(written_data)
  File "/home/mathis/anaconda3/lib/python3.12/site-packages/wandb/sdk/wandb_run.py", line 2500, in <lambda>
    lambda data: self._console_raw_callback("stderr", data),
                 ^^^^^^^^^^^^^^^^^^^^^^^^^^^^^^^^^^^^^^^^^^
  File "/home/mathis/anaconda3/lib/python3.12/site-packages/wandb/sdk/wandb_run.py", line 406, in wrapper
    return func(self, *args, **kwargs)
           ^^^^^^^^^^^^^^^^^^^^^^^^^^^
  File "/home/mathis/anaconda3/lib/python3.12/site-packages/wandb/sdk/wandb_run.py", line 464, in wrapper_fn
    return func(self, *args, **kwargs)
           ^^^^^^^^^^^^^^^^^^^^^^^^^^^
  File "/home/mathis/anaconda3/lib/python3.12/site-packages/wandb/sdk/wandb_run.py", line 1639, in _console_raw_callback
    self._backend.interface.publish_output_raw(name, data)
  File "/home/mathis/anaconda3/lib/python3.12/site-packages/wandb/sdk/interface/interface.py", line 762, in publish_output_raw
    self._publish_output_raw(o)
  File "/home/mathis/anaconda3/lib/python3.12/site-packages/wandb/sdk/interface/interface_shared.py", line 38, in _publish_output_raw
    self._publish(rec)
  File "/home/mathis/anaconda3/lib/python3.12/site-packages/wandb/sdk/interface/interface_sock.py", line 39, in _publish
    self._sock_client.send_record_publish(record)
  File "/home/mathis/anaconda3/lib/python3.12/site-packages/wandb/sdk/lib/sock_client.py", line 174, in send_record_publish
    self.send_server_request(server_req)
  File "/home/mathis/anaconda3/lib/python3.12/site-packages/wandb/sdk/lib/sock_client.py", line 154, in send_server_request
    self._send_message(msg)
  File "/home/mathis/anaconda3/lib/python3.12/site-packages/wandb/sdk/lib/sock_client.py", line 151, in _send_message
    self._sendall_with_error_handle(header + data)
  File "/home/mathis/anaconda3/lib/python3.12/site-packages/wandb/sdk/lib/sock_client.py", line 130, in _sendall_with_error_handle
    sent = self._sock.send(data)
           ^^^^^^^^^^^^^^^^^^^^^
BrokenPipeError: [Errno 32] Broken pipe
2025-05-10 17:52:01,165 INFO    MainThread:9122 [wandb_init.py:_post_run_cell_hook():613] [no run ID] resuming backend
2025-05-10 17:52:01,166 ERROR   MainThread:9122 [redirect.py:_on_write():664] [no run ID] error in stdout callback
Traceback (most recent call last):
  File "/home/mathis/anaconda3/lib/python3.12/site-packages/IPython/core/events.py", line 82, in trigger
    func(*args, **kwargs)
  File "/home/mathis/anaconda3/lib/python3.12/site-packages/wandb/sdk/wandb_init.py", line 614, in _post_run_cell_hook
    self.backend.interface.publish_resume()
  File "/home/mathis/anaconda3/lib/python3.12/site-packages/wandb/sdk/interface/interface.py", line 778, in publish_resume
    self._publish_resume(resume)
  File "/home/mathis/anaconda3/lib/python3.12/site-packages/wandb/sdk/interface/interface_shared.py", line 293, in _publish_resume
    self._publish(rec)
  File "/home/mathis/anaconda3/lib/python3.12/site-packages/wandb/sdk/interface/interface_sock.py", line 39, in _publish
    self._sock_client.send_record_publish(record)
  File "/home/mathis/anaconda3/lib/python3.12/site-packages/wandb/sdk/lib/sock_client.py", line 174, in send_record_publish
    self.send_server_request(server_req)
  File "/home/mathis/anaconda3/lib/python3.12/site-packages/wandb/sdk/lib/sock_client.py", line 154, in send_server_request
    self._send_message(msg)
  File "/home/mathis/anaconda3/lib/python3.12/site-packages/wandb/sdk/lib/sock_client.py", line 151, in _send_message
    self._sendall_with_error_handle(header + data)
  File "/home/mathis/anaconda3/lib/python3.12/site-packages/wandb/sdk/lib/sock_client.py", line 130, in _sendall_with_error_handle
    sent = self._sock.send(data)
           ^^^^^^^^^^^^^^^^^^^^^
BrokenPipeError: [Errno 32] Broken pipe

During handling of the above exception, another exception occurred:

Traceback (most recent call last):
  File "/home/mathis/anaconda3/lib/python3.12/site-packages/wandb/sdk/lib/redirect.py", line 662, in _on_write
    cb(written_data)
  File "/home/mathis/anaconda3/lib/python3.12/site-packages/wandb/sdk/wandb_run.py", line 2494, in <lambda>
    lambda data: self._console_raw_callback("stdout", data),
                 ^^^^^^^^^^^^^^^^^^^^^^^^^^^^^^^^^^^^^^^^^^
  File "/home/mathis/anaconda3/lib/python3.12/site-packages/wandb/sdk/wandb_run.py", line 406, in wrapper
    return func(self, *args, **kwargs)
           ^^^^^^^^^^^^^^^^^^^^^^^^^^^
  File "/home/mathis/anaconda3/lib/python3.12/site-packages/wandb/sdk/wandb_run.py", line 464, in wrapper_fn
    return func(self, *args, **kwargs)
           ^^^^^^^^^^^^^^^^^^^^^^^^^^^
  File "/home/mathis/anaconda3/lib/python3.12/site-packages/wandb/sdk/wandb_run.py", line 1639, in _console_raw_callback
    self._backend.interface.publish_output_raw(name, data)
  File "/home/mathis/anaconda3/lib/python3.12/site-packages/wandb/sdk/interface/interface.py", line 762, in publish_output_raw
    self._publish_output_raw(o)
  File "/home/mathis/anaconda3/lib/python3.12/site-packages/wandb/sdk/interface/interface_shared.py", line 38, in _publish_output_raw
    self._publish(rec)
  File "/home/mathis/anaconda3/lib/python3.12/site-packages/wandb/sdk/interface/interface_sock.py", line 39, in _publish
    self._sock_client.send_record_publish(record)
  File "/home/mathis/anaconda3/lib/python3.12/site-packages/wandb/sdk/lib/sock_client.py", line 174, in send_record_publish
    self.send_server_request(server_req)
  File "/home/mathis/anaconda3/lib/python3.12/site-packages/wandb/sdk/lib/sock_client.py", line 154, in send_server_request
    self._send_message(msg)
  File "/home/mathis/anaconda3/lib/python3.12/site-packages/wandb/sdk/lib/sock_client.py", line 151, in _send_message
    self._sendall_with_error_handle(header + data)
  File "/home/mathis/anaconda3/lib/python3.12/site-packages/wandb/sdk/lib/sock_client.py", line 130, in _sendall_with_error_handle
    sent = self._sock.send(data)
           ^^^^^^^^^^^^^^^^^^^^^
BrokenPipeError: [Errno 32] Broken pipe
2025-05-10 17:52:01,169 ERROR   MainThread:9122 [redirect.py:_on_write():664] [no run ID] error in stdout callback
Traceback (most recent call last):
  File "/home/mathis/anaconda3/lib/python3.12/site-packages/IPython/core/events.py", line 82, in trigger
    func(*args, **kwargs)
  File "/home/mathis/anaconda3/lib/python3.12/site-packages/wandb/sdk/wandb_init.py", line 614, in _post_run_cell_hook
    self.backend.interface.publish_resume()
  File "/home/mathis/anaconda3/lib/python3.12/site-packages/wandb/sdk/interface/interface.py", line 778, in publish_resume
    self._publish_resume(resume)
  File "/home/mathis/anaconda3/lib/python3.12/site-packages/wandb/sdk/interface/interface_shared.py", line 293, in _publish_resume
    self._publish(rec)
  File "/home/mathis/anaconda3/lib/python3.12/site-packages/wandb/sdk/interface/interface_sock.py", line 39, in _publish
    self._sock_client.send_record_publish(record)
  File "/home/mathis/anaconda3/lib/python3.12/site-packages/wandb/sdk/lib/sock_client.py", line 174, in send_record_publish
    self.send_server_request(server_req)
  File "/home/mathis/anaconda3/lib/python3.12/site-packages/wandb/sdk/lib/sock_client.py", line 154, in send_server_request
    self._send_message(msg)
  File "/home/mathis/anaconda3/lib/python3.12/site-packages/wandb/sdk/lib/sock_client.py", line 151, in _send_message
    self._sendall_with_error_handle(header + data)
  File "/home/mathis/anaconda3/lib/python3.12/site-packages/wandb/sdk/lib/sock_client.py", line 130, in _sendall_with_error_handle
    sent = self._sock.send(data)
           ^^^^^^^^^^^^^^^^^^^^^
BrokenPipeError: [Errno 32] Broken pipe

During handling of the above exception, another exception occurred:

Traceback (most recent call last):
  File "/home/mathis/anaconda3/lib/python3.12/site-packages/wandb/sdk/lib/redirect.py", line 662, in _on_write
    cb(written_data)
  File "/home/mathis/anaconda3/lib/python3.12/site-packages/wandb/sdk/wandb_run.py", line 2494, in <lambda>
    lambda data: self._console_raw_callback("stdout", data),
                 ^^^^^^^^^^^^^^^^^^^^^^^^^^^^^^^^^^^^^^^^^^
  File "/home/mathis/anaconda3/lib/python3.12/site-packages/wandb/sdk/wandb_run.py", line 406, in wrapper
    return func(self, *args, **kwargs)
           ^^^^^^^^^^^^^^^^^^^^^^^^^^^
  File "/home/mathis/anaconda3/lib/python3.12/site-packages/wandb/sdk/wandb_run.py", line 464, in wrapper_fn
    return func(self, *args, **kwargs)
           ^^^^^^^^^^^^^^^^^^^^^^^^^^^
  File "/home/mathis/anaconda3/lib/python3.12/site-packages/wandb/sdk/wandb_run.py", line 1639, in _console_raw_callback
    self._backend.interface.publish_output_raw(name, data)
  File "/home/mathis/anaconda3/lib/python3.12/site-packages/wandb/sdk/interface/interface.py", line 762, in publish_output_raw
    self._publish_output_raw(o)
  File "/home/mathis/anaconda3/lib/python3.12/site-packages/wandb/sdk/interface/interface_shared.py", line 38, in _publish_output_raw
    self._publish(rec)
  File "/home/mathis/anaconda3/lib/python3.12/site-packages/wandb/sdk/interface/interface_sock.py", line 39, in _publish
    self._sock_client.send_record_publish(record)
  File "/home/mathis/anaconda3/lib/python3.12/site-packages/wandb/sdk/lib/sock_client.py", line 174, in send_record_publish
    self.send_server_request(server_req)
  File "/home/mathis/anaconda3/lib/python3.12/site-packages/wandb/sdk/lib/sock_client.py", line 154, in send_server_request
    self._send_message(msg)
  File "/home/mathis/anaconda3/lib/python3.12/site-packages/wandb/sdk/lib/sock_client.py", line 151, in _send_message
    self._sendall_with_error_handle(header + data)
  File "/home/mathis/anaconda3/lib/python3.12/site-packages/wandb/sdk/lib/sock_client.py", line 130, in _sendall_with_error_handle
    sent = self._sock.send(data)
           ^^^^^^^^^^^^^^^^^^^^^
BrokenPipeError: [Errno 32] Broken pipe
